<?xml version="1.0"?>
<robot name="monoped">

    <link name="base_link">
        <inertial>
            <origin xyz="0 0 0" rpy="0 0 0"/>
            <mass value="31.5" />
            <inertia ixx="0.00506133333333" ixy="0.0" ixz="0.0" iyy="0.00506133333333" iyz="0.0" izz="0.00293333333333"/>
        </inertial>
        <collision>
            <origin xyz="0 0 0" rpy="0 0 0"/>
            <geometry>
                <box size="0.20 0.20 0.30"/>
            </geometry>
        </collision>
	    <visual>
	      <geometry>
	        <box size="0.20 0.20 0.30"/>
	      </geometry>
	      <material name="blue">
	        <color rgba="0 0 1.0 1.0"/>
	      </material>
	    </visual>
    </link>

    <gazebo reference="base_link">
        <kp>1000.0</kp>
        <kd>1000.0</kd>
        <mu1>0.5</mu1>
        <mu2>0.5</mu2>
        <material>Gazebo/Blue</material>
    </gazebo>
    
    <link name="hipassembly">
        <inertial>
            <origin xyz="0 0 0" rpy="0 0 0"/>
            <mass value="7.5" />
            <inertia ixx="0.00140906974933" ixy="0.0" ixz="0.0" iyy="0.001529597616" iyz="0.0" izz="0.000218659333333"/>
        </inertial>
        <collision>
            <origin rpy="0.0 0.0 0.0" xyz="0.0 0.0 0.0"/>
	      <geometry>
	        <mesh filename="package://hopper_robot_desc/meshes/leg/hipassembly.dae" scale="1 1 1"/>
	      </geometry>
        </collision>
	    <visual>
	      <origin rpy="0.0 0.0 0.0" xyz="0.0 0.0 0.0"/>
	      <geometry>
	        <mesh filename="package://hopper_robot_desc/meshes/leg/hipassembly.dae" scale="1 1 1"/>
	      </geometry>
	    </visual>
    </link>

    <gazebo reference="hipassembly">
        <kp>1000.0</kp>
        <kd>1000.0</kd>
        <mu1>0.5</mu1>
        <mu2>0.5</mu2>
    </gazebo>


    <link name="upperleg">
        <inertial>
            <origin xyz="0 0 0" rpy="0 0 0"/>
            <mass value="7.5" />
            <inertia ixx="0.000119502849333" ixy="0.0" ixz="0.0" iyy="0.00158478921733" iyz="0.0" izz="0.00158585686667"/>
        </inertial>
        <collision>
            <origin rpy="0.0 0.0 0.0" xyz="0.0 0.0 0.0"/>
	      <geometry>
	        <mesh filename="package://hopper_robot_desc/meshes/leg/upperleg.dae" scale="1 1 1"/>
	      </geometry>
        </collision>
	    <visual>
	      <origin rpy="0.0 0.0 0.0" xyz="0.0 0.0 0.0"/>
	      <geometry>
	        <mesh filename="package://hopper_robot_desc/meshes/leg/upperleg.dae" scale="1 1 1"/>
	      </geometry>
	    </visual>
    </link>

    <gazebo reference="upperleg">
        <kp>1000.0</kp>
        <kd>1000.0</kd>
        <mu1>0.5</mu1>
        <mu2>0.5</mu2>
    </gazebo>

    <link name="lowerleg">
        <inertial>
            <origin xyz="0 0 0" rpy="0 0 0"/>
            <mass value="1.95" />
            <inertia ixx="1.74153666667e-05" ixy="0.0" ixz="0.0" iyy="0.000370889177667" iyz="0.0" izz="0.000363771677667"/>
        </inertial>
        <collision>
            <origin rpy="0.0 0.0 0.0" xyz="0.0 0.0 0.0"/>
	      <geometry>
	        <mesh filename="package://hopper_robot_desc/meshes/leg/lowerleg.dae" scale="1 1 1"/>
	      </geometry>
        </collision>
	    <visual>
	      <geometry>
	        <mesh filename="package://hopper_robot_desc/meshes/leg/lowerleg.dae" scale="1 1 1"/>
	      </geometry>
	    </visual>
    </link>

   <gazebo reference="lowerleg">
        <kp>1000.0</kp>
        <kd>1000.0</kd>
        <mu1>0.5</mu1>
        <mu2>0.5</mu2>
    </gazebo>

    <link name="contactsensor_link">
 	    <inertial >
            <origin xyz="0 0 0" rpy="0 0 0"/>
            <mass value="0.8" />
            <inertia ixx="1.28e-06" ixy="0.0" ixz="0.0" iyy="1.28e-06" iyz="0.0" izz="1.28e-06"/>
        </inertial>
        <collision>
            <origin xyz="0 0 0" rpy="0 0 0"/>
            <geometry>
                
                <sphere radius="0.030"/>
                <!--
                <box size="0.15 0.15 0.15"/>
                -->
                
                <sphere radius="0.08"/>
            </geometry>
        </collision>
        <visual>
            <origin rpy="0.0 0 0" xyz="0 0 0"/>
            <geometry>
                
                <sphere radius="0.030"/>
                <!--
                <box size="0.15 0.15 0.15"/>
                -->
                
                <sphere radius="0.08"/>
            </geometry>
        </visual>
	</link>

    <gazebo reference="contactsensor_link">
        <material>Gazebo/Blue</material>
        <kp>1000.0</kp>
        <kd>1000.0</kd>
        <mu1>10.0</mu1>
        <mu2>10.0</mu2>


       <!-- <sensor name="contactsensor_sensor" type="contact">
          <always_on>true</always_on>
          <contact>
            <collision>lowerleg_fixed_joint_lump__contactsensor_link_collision_1</collision>
          </contact>
          <plugin name="bumper0_plugin" filename="libgazebo_ros_bumper.so">
            <bumperTopicName>lowerleg_contactsensor_state</bumperTopicName>
            <frameName>contactsensor_link</frameName>
          </plugin>
        </sensor> -->

    </gazebo>

    <joint name="lowerleg_contactsensor_link_joint" type="fixed">
        <parent link="lowerleg"/>
        <child link="contactsensor_link"/>
        <origin xyz="0.35 0 0" rpy="0 0 0"/>
    </joint>

    
    <joint name="haa_joint" type="revolute">
        <origin xyz="0.0 0.0 -0.15000" rpy="2.0344439357957036 1.5707962290814481 -1.1071487177940917"/>
        <parent link="base_link"/>
        <child  link="hipassembly"/>
        <limit effort="200" lower="-1.6" upper="1.6" velocity="1.0"/>
        <axis xyz="0 0 1"/>
    </joint>
    <joint name="hfe_joint" type="revolute">
        <origin xyz="0.08000 0.00000 0.00000" rpy="1.5707963705062866 -0.0 0.0"/>
        <parent link="hipassembly"/>
        <child  link="upperleg"/>
        <limit effort="200" lower="-1.6" upper="1.6" velocity="1.0"/>
        <axis xyz="0 0 1"/>
    </joint>
    <joint name="kfe_joint" type="revolute">
        <origin xyz="0.35000 0.00000 0.00000" rpy="0.0 0.0 0.0"/>
        <parent link="upperleg"/>
        <child  link="lowerleg"/>
        <limit effort="200" lower="-1.6" upper="1.6" velocity="1.0"/>
        <axis xyz="0 0 1"/>
    </joint>
</robot>

